Workbook

Sheet Dataset1_Monthly_Frequency
B1: DATASET 1 (Mensual): todas las variables, macro + financieras, 2003-2026, ~276 observaciones.
B2: Rentabilidad REIT USA | D2: Tipos de interes | G2: Inflación | I2: Crecimiento económico | J2: Mercado Financiero | L2: Mercado Inmobiliario
A3: observation_date | B3: FTSE Nareit All Equity REITs Index | C3: MSCI US REIT Index | D3: 10Y Treasury | E3: 2Y | F3: Fed Fund Rate | G3: ACPI YoY | H3: Break Even Inflation | I3: Industrial Production | J3: Spread Crédito( BBB- Treasury) | K3: VIX (Cambio Mensual) | L3: Case-Shiller | M3: Housing Starts | N3: Building Permits
A4: 37622 | B4: -0.03220938 | C4: -0.027524008 | D4: 4.05 | E4: 1.74 | F4: 1.24 | G4: 2.7575 | H4: 1.75 | I4: 91.2361 | J4: 3.3 | K4: 27.42 | L4: 128.462 | M4: 1853 | N4: 1808
A5: 37653 | B5: 0.01076414 | C5: 0.017899618 | D5: 3.9 | E5: 1.63 | F5: 1.26 | G5: 3.1461 | H5: 1.91 | I5: 91.3445 | J5: 3.15 | K5: 32.22 | L5: 129.357 | M5: 1629 | N5: 1854
A6: 37681 | B6: 0.01113871 | C6: 0.021007412 | D6: 3.81 | E6: 1.57 | F6: 1.25 | G6: 3.0252 | H6: 1.86 | I6: 91.1044 | J6: 3.14 | K6: 30.63 | L6: 130.148 | M6: 1726 | N6: 1757
A7: 37712 | B7: 0.04037961 | C7: 0.042213797 | D7: 3.96 | E7: 1.62 | F7: 1.26 | G7: 2.1751 | H7: 1.77 | I7: 90.5617 | J7: 2.89 | K7: 23.99 | L7: 130.884 | M7: 1643 | N7: 1803
A8: 37742 | B8: 0.05419424 | C8: 0.05649705 | D8: 3.57 | E8: 1.42 | F8: 1.26 | G8: 1.8942 | H8: 1.66 | I8: 90.537 | J8: 2.81 | K8: 20.24 | L8: 131.735 | M8: 1751 | N8: 1835
A9: 37773 | B9: 0.01452324 | C9: 0.02315816 | D9: 3.33 | E9: 1.23 | F9: 1.22 | G9: 1.9488 | H9: 1.61 | I9: 90.6527 | J9: 2.86 | K9: 20.36 | L9: 132.649 | M9: 1867 | N9: 1875
A10: 37803 | B10: 0.0493344 | C10: 0.053065747 | D10: 3.98 | E10: 1.47 | F10: 1.01 | G10: 2.0556 | H10: 1.87 | I10: 91.1185 | J10: 2.64 | K10: 19.16 | L10: 133.777 | M10: 1897 | N10: 1885
A11: 37834 | B11: 0.00066937 | C11: 0.0060992244 | D11: 4.45 | E11: 1.86 | F11: 1.03 | G11: 2.2161 | H11: 2.12 | I11: 90.9197 | J11: 2.57 | K11: 19.27 | L11: 134.968 | M11: 1833 | N11: 1966
A12: 37865 | B12: 0.02647003 | C12: 0.035288877 | D12: 4.27 | E12: 1.71 | F12: 1.01 | G12: 2.3783 | H12: 2.09 | I12: 91.5059 | J12: 2.52 | K12: 19.53 | L12: 136.295 | M12: 1939 | N12: 1961
A13: 37895 | B13: 0.01442979 | C13: 0.01685593 | D13: 4.29 | E13: 1.75 | F13: 1.01 | G13: 2.0419 | H13: 2.21 | I13: 91.6186 | J13: 2.44 | K13: 18.02 | L13: 137.533 | M13: 1967 | N13: 2012
A14: 37926 | B14: 0.03912511 | C14: 0.043934209 | D14: 4.3 | E14: 1.93 | F14: 1 | G14: 1.9284 | H14: 2.34 | I14: 92.2329 | J14: 2.36 | K14: 17.4 | L14: 138.795 | M14: 2083 | N14: 1918
A15: 37956 | B15: 0.02746622 | C15: 0.031422932 | D15: 4.27 | E15: 1.91 | F15: 0.98 | G15: 2.0352 | H15: 2.28 | I15: 92.2602 | J15: 2.33 | K15: 16.83 | L15: 140.182 | M15: 2057 | N15: 1987
... A276: 45901 | B276: -0.00277261 | C276: 0.011524701 | D276: 4.12 | E276: 3.57 | F276: 4.22 | G276: 3.0226 | H276: 2.37 | I276: 101.668 | J276: 1.71 | K276: 15.79 | L276: 327.646 | M276: 1328 | N276: 1415
A277: 45931 | B277: -0.02329802 | C277: -0.015568587 | D277: 4.06 | E277: 3.52 | F277: 4.09 | H277: 2.31 | I277: 101.2195 | J277: 1.67 | K277: 18.09 | L277: 328.74 | M277: 1272 | N277: 1411
A278: 45962 | B278: 0.02082263 | C278: 0.022607917 | D278: 4.09 | E278: 3.55 | F278: 3.88 | G278: 2.6964 | H278: 2.27 | I278: 101.081 | J278: 1.76 | K278: 19.77 | L278: 330.073 | M278: 1324 | N278: 1388
A279: 45992 | B279: -0.02833757 | C279: 0 | D279: 4.14 | E279: 3.5 | F279: 3.72 | G279: 2.6533 | H279: 2.24 | I279: 101.6113 | J279: 1.75 | K279: 15.55 | L279: 331.258 | M279: 1373 | N279: 1455
A280: 46023 | B280: 0.11662946 | D280: 4.21 | E280: 3.54 | F280: 3.64 | G280: 2.3912 | H280: 2.31 | I280: 101.5954 | J280: 1.67 | K280: 16.18 | L280: 331.801 | M280: 1398 | N280: 1386
B281: -0.08066205

Sheet Dataset2_Weekly_Frequency
B1: DATASET 2 (Semanal): solo variables financieras, 2003-2026, ~1.200 observaciones
B2: Rentabilidad REIT USA | D2: Tipos de interes | F2: Inflación | G2: Mercado Financiero
A3: Observation_date | B3: FTSE Nareit All Equity REITs Index | C3: MSCI US REIT Index | D3: 10Y Treasury | E3: 2Y | F3: T10YIE | G3: Spread Crédito( BBB- Treasury) | H3: VIX (Cambio Mensual)
A4: 37631 | C4: =(#REF!-#REF!)/#REF! -> #REF! | D4: 4.1 | E4: 1.8 | F4: 1.7 | G4: 3.34 | H4: 24.83
A5: 37638 | B5: =(FTSE_NAREIT!R21/FTSE_NAREIT!R20)-1 -> -0.025252626 | C5: =(#REF!-#REF!)/#REF! -> #REF! | D5: 4.1 | E5: 1.75 | F5: 1.78 | G5: 3.29 | H5: 25.14
A6: 37645 | B6: =(FTSE_NAREIT!R22/FTSE_NAREIT!R21)-1 -> -0.011926341 | C6: =(#REF!-#REF!)/#REF! -> #REF! | D6: 3.97 | E6: 1.67 | F6: 1.77 | G6: 3.33 | H6: 28.91
A7: 37652 | B7: =(FTSE_NAREIT!R23/FTSE_NAREIT!R22)-1 -> 0.01557448 | C7: =(#REF!-#REF!)/#REF! -> #REF! | D7: 4.01 | E7: 1.72 | F7: 1.82 | G7: 3.21 | H7: 32.07
A8: 37659 | B8: =(FTSE_NAREIT!R24/FTSE_NAREIT!R23)-1 -> -0.0076344731 | C8: =(#REF!-#REF!)/#REF! -> #REF! | D8: 3.98 | E8: 1.69 | F8: 1.86 | G8: 3.12 | H8: 32.84
A9: 37666 | B9: =(FTSE_NAREIT!R25/FTSE_NAREIT!R24)-1 -> -0.0082366691 | C9: =(#REF!-#REF!)/#REF! -> #REF! | D9: 3.95 | E9: 1.63 | F9: 1.91 | G9: 3.15 | H9: 33.66
A10: 37673 | B10: =(FTSE_NAREIT!R26/FTSE_NAREIT!R25)-1 -> 0.028521261 | C10: =(#REF!-#REF!)/#REF! -> #REF! | D10: 3.89 | E10: 1.62 | F10: 1.92 | G10: 3.17 | H10: 30.96
A11: 37680 | B11: =(FTSE_NAREIT!R27/FTSE_NAREIT!R26)-1 -> 0.004230734 | C11: =(#REF!-#REF!)/#REF! -> #REF! | D11: 3.78 | E11: 1.57 | F11: 1.96 | G11: 3.19 | H11: 31.16
A12: 37687 | B12: =(FTSE_NAREIT!R28/FTSE_NAREIT!R27)-1 -> -0.0087481353 | C12: =(#REF!-#REF!)/#REF! -> #REF! | D12: 3.65 | E12: 1.47 | F12: 1.9 | G12: 3.25 | H12: 31.02
A13: 37694 | B13: =(FTSE_NAREIT!R29/FTSE_NAREIT!R28)-1 -> -0.0055478502 | C13: =(#REF!-#REF!)/#REF! -> #REF! | D13: 3.65 | E13: 1.47 | F13: 1.92 | G13: 3.25 | H13: 32.63
A14: 37701 | B14: =(FTSE_NAREIT!R30/FTSE_NAREIT!R29)-1 -> 0.059182162 | C14: =(#REF!-#REF!)/#REF! -> #REF! | D14: 3.97 | E14: 1.72 | F14: 1.83 | G14: 3.07 | H14: 30.57
A15: 37708 | B15: =(FTSE_NAREIT!R31/FTSE_NAREIT!R30)-1 -> -0.015626409 | C15: =(#REF!-#REF!)/#REF! -> #REF! | D15: 3.96 | E15: 1.65 | F15: 1.82 | G15: 3.02 | H15: 28.62
A16: 37715 | B16: =(FTSE_NAREIT!R32/FTSE_NAREIT!R31)-1 -> 0.010570954 | C16: =(#REF!-#REF!)/#REF! -> #REF! | D16: 3.9 | E16: 1.54 | F16: 1.81 | G16: 3.01 | H16: 28.57
... A1203: 46024 | B1203: =(FTSE_NAREIT!R1219/FTSE_NAREIT!R1218)-1 -> -0.0014248575 | C1203: =(#REF!-#REF!)/#REF! -> #REF! | D1203: 4.16 | E1203: 3.46 | F1203: 2.24 | G1203: 1.74 | H1203: 14.5
B1204: =(FTSE_NAREIT!R1220/FTSE_NAREIT!R1219)-1 -> 0.0092819894
B1205: =(FTSE_NAREIT!R1221/FTSE_NAREIT!R1220)-1 -> 0.035062119
B1206: =(FTSE_NAREIT!R1222/FTSE_NAREIT!R1221)-1 -> -0.023540644
B1207: =(FTSE_NAREIT!R1223/FTSE_NAREIT!R1222)-1 -> 0.0059742038
B1208: =(FTSE_NAREIT!R1224/FTSE_NAREIT!R1223)-1 -> 0.023211281
B1209: =(FTSE_NAREIT!R1225/FTSE_NAREIT!R1224)-1 -> 0.040399865
B1210: =(FTSE_NAREIT!R1226/FTSE_NAREIT!R1225)-1 -> -0.0007559106
B1211: =(FTSE_NAREIT!R1227/FTSE_NAREIT!R1226)-1 -> 0.010626222
B1212: =(FTSE_NAREIT!R1228/FTSE_NAREIT!R1227)-1 -> -0.020734367
B1213: =(FTSE_NAREIT!R1229/FTSE_NAREIT!R1228)-1 -> -0.013579417
B1214: =(FTSE_NAREIT!R1230/FTSE_NAREIT!R1229)-1 -> -0.038654751
B1215: =(FTSE_NAREIT!R1231/FTSE_NAREIT!R1230)-1 -> -0.0076397303
... B1220: =(FTSE_NAREIT!R1236/FTSE_NAREIT!R1235)-1 -> 0.011877412

Sheet FTSE_NAREIT
A1: DATASERT 1 MONTHLY FREQUENCY | M1: DATASET 2 DFRECUENCIA SEMANAL
A2: Price History: FNERXXXX | M2: Price History: FNERXXXX
A4: . | M4: .
A18: Price History: FNERXXXX | M18: Price History: FNERXXXX
M19: Date | N19: Price | O19: CVol | P19: Change | Q19: % Change | R19: Total Return (Gross, Unhedged) | S19: Cumulative Return % (Gross, Unhedged) | T19: Open | U19: High | V19: Low | W19: FTSE_NAREIT
A20: Date | B20: Price | C20: CVol | D20: Change | E20: % Change | F20: Total Return (Gross, Unhedged) | G20: Cumulative Return % (Gross, Unhedged) | H20: Open | I20: High | J20: Low | K20: FTSE_NAREIT | M20: 37631 | N20: 269.44 | P20: -5.53 | Q20: -2.0111285 | R20: 3525.97 | S20: 48.373183 | U20: 269.44 | V20: 269.44 | W20: =(R20/#REF!)-1 -> #REF!
A21: 01/31/00 | B21: 227.34 | F21: 2384.25 | I21: 227.34 | J21: 227.34 | M21: 37638 | N21: 262.52 | P21: -6.92 | Q21: -2.5682898 | R21: 3436.93 | S21: 44.626371 | U21: 262.52 | V21: 262.52 | W21: =(R21/R20)-1 -> -0.025252626
A22: 02/29/00 | B22: 223.26 | D22: -4.08 | E22: -1.79 | F22: 2355.84 | G22: -1.19 | I22: 223.26 | J22: 223.26 | K22: =(F22-F21)-1 -> -29.41 | M22: 37645 | N22: 259.22 | P22: -3.3 | Q22: -1.2570471 | R22: 3395.94 | S22: 42.901507 | U22: 259.22 | V22: 259.22 | W22: =(R22/R21)-1 -> -0.011926341
A23: 03/31/00 | B23: 228.39 | D23: 5.13 | E23: 2.3 | F23: 2433.3 | G23: 2.06 | I23: 228.39 | J23: 228.39 | K23: =(F23-F22)-1 -> 76.46 | M23: 37652 | N23: 262.91 | P23: 3.69 | Q23: 1.4235013 | R23: 3448.83 | S23: 45.127124 | U23: 262.91 | V23: 262.91 | W23: =(R23/R22)-1 -> 0.01557448
A24: 04/28/00 | B24: 242.59 | D24: 14.2 | E24: 6.22 | F24: 2596.8 | G24: 8.91 | I24: 242.59 | J24: 242.59 | K24: =(F24-F23)-1 -> 162.5 | M24: 37659 | N24: 260.55 | P24: -2.36 | Q24: -0.89764558 | R24: 3422.5 | S24: 44.019155 | U24: 260.55 | V24: 260.55 | W24: =(R24/R23)-1 -> -0.0076344731
A25: 05/31/00 | B25: 243.55 | D25: 0.96 | E25: 0.4 | F25: 2622.34 | G25: 9.99 | I25: 243.55 | J25: 243.55 | K25: =(F25-F24)-1 -> 24.54 | M25: 37666 | N25: 257.44 | P25: -3.11 | Q25: -1.1936289 | R25: 3394.31 | S25: 42.832917 | U25: 257.44 | V25: 257.44 | W25: =(R25/R24)-1 -> -0.0082366691
A26: 06/30/00 | B26: 247.66 | D26: 4.11 | E26: 1.69 | F26: 2689.61 | G26: 12.81 | I26: 247.66 | J26: 247.66 | K26: =(F26-F25)-1 -> 66.27 | M26: 37673 | N26: 264.71 | P26: 7.27 | Q26: 2.823959 | R26: 3491.12 | S26: 46.906692 | U26: 264.71 | V26: 264.71 | W26: =(R26/R25)-1 -> 0.028521261
A27: 07/31/00 | B27: 268.29 | D27: 20.63 | E27: 8.33 | F27: 2924.69 | G27: 22.67 | I27: 268.29 | J27: 268.29 | K27: =(F27-F26)-1 -> 234.08 | M27: 37680 | N27: 265.74 | P27: 1.03 | Q27: 0.38910506 | R27: 3505.89 | S27: 47.528215 | U27: 265.74 | V27: 265.74 | W27: =(R27/R26)-1 -> 0.004230734
A28: 08/31/00 | B28: 255.96 | D28: -12.33 | E28: -4.6 | F28: 2805.99 | G28: 17.69 | I28: 255.96 | J28: 255.96 | K28: =(F28-F27)-1 -> -119.7 | M28: 37687 | N28: 263.36 | P28: -2.38 | Q28: -0.89561225 | R28: 3475.22 | S28: 46.237618 | U28: 263.36 | V28: 263.36 | W28: =(R28/R27)-1 -> -0.0087481353
A29: 09/29/00 | B29: 261.7 | D29: 5.74 | E29: 2.24 | F29: 2895.27 | G29: 21.43 | I29: 261.7 | J29: 261.7 | K29: =(F29-F28)-1 -> 88.28 | M29: 37694 | N29: 261.59 | P29: -1.77 | Q29: -0.67208384 | R29: 3455.94 | S29: 45.426314 | U29: 261.59 | V29: 261.59 | W29: =(R29/R28)-1 -> -0.0055478502
A30: 10/31/00 | B30: 249.2 | D30: -12.5 | E30: -4.78 | F30: 2769.93 | G30: 16.18 | I30: 249.2 | J30: 249.2 | K30: =(F30-F29)-1 -> -126.34 | M30: 37701 | N30: 276.6 | P30: 15.01 | Q30: 5.7379869 | R30: 3660.47 | S30: 54.032957 | U30: 276.6 | V30: 276.6 | W30: =(R30/R29)-1 -> 0.059182162
A31: 11/30/00 | B31: 251.04 | D31: 1.84 | E31: 0.74 | F31: 2805.5 | G31: 17.67 | I31: 251.04 | J31: 251.04 | K31: =(F31-F30)-1 -> 34.57 | M31: 37708 | N31: 270.74 | P31: -5.86 | Q31: -2.1185828 | R31: 3603.27 | S31: 51.625975 | U31: 270.74 | V31: 270.74 | W31: =(R31/R30)-1 -> -0.015626409
A32: 12/29/00 | B32: 264.9 | D32: 13.86 | E32: 5.52 | F32: 3002.97 | G32: 25.95 | I32: 264.9 | J32: 264.9 | K32: =(F32-F31)-1 -> 196.47 | M32: 37715 | N32: 273.22 | P32: 2.48 | Q32: 0.91600798 | R32: 3641.36 | S32: 53.228806 | U32: 273.22 | V32: 273.22 | W32: =(R32/R31)-1 -> 0.010570954
A33: 01/31/01 | B33: 266.87 | D33: 1.97 | E33: 0.74 | F33: 3034.31 | G33: 27.26 | I33: 266.87 | J33: 266.87 | K33: =(F33-F32)-1 -> 30.34 | M33: 37722 | N33: 273.45 | P33: 0.23 | Q33: 0.084181246 | R33: 3645.82 | S33: 53.416484 | U33: 273.45 | V33: 273.45 | W33: =(R33/R32)-1 -> 0.0012248171
... A336: 04/30/26 | B336: 842.15 | D336: 68.57 | E336: 8.86 | F336: 29045.85 | G336: 1118.24 | I336: 842.15 | J336: 842.15 | K336: =(F336-F335)-1 -> 2407.43 | M336: 39843 | N336: 235.73 | P336: -7.93 | Q336: -3.254535 | R336: 4215.2 | S336: 77.376053 | U336: 235.73 | V336: 235.73 | W336: =(R336/R335)-1 -> -0.031894297
A337: 46027 | B337: 840.42 | D337: -1.74 | E337: -0.21 | F337: 28986 | G337: 1115.73 | I337: 840.42 | J337: 840.42 | K337: =(F337-F336)-1 -> -60.85 | M337: 39850 | N337: 244.53 | P337: 8.8 | Q337: 3.7330845 | R337: 4381.49 | S337: 84.373553 | U337: 244.53 | V337: 244.53 | W337: =(R337/R336)-1 -> 0.039450085
M338: 39857 | N338: 211.01 | P338: -33.52 | Q338: -13.707929 | R338: 3786.42 | S338: 59.332946 | U338: 211.01 | V338: 211.01 | W338: =(R338/R337)-1 -> -0.13581453
M339: 39864 | N339: 202.34 | P339: -8.67 | Q339: -4.10881 | R339: 3638.3 | S339: 53.100041 | U339: 202.34 | V339: 202.34 | W339: =(R339/R338)-1 -> -0.039118745
M340: 39871 | N340: 185.56 | P340: -16.78 | Q340: -8.2929722 | R340: 3337.41 | S340: 40.438559 | U340: 185.56 | V340: 185.56 | W340: =(R340/R339)-1 -> -0.082700712
M341: 39878 | N341: 163.57 | P341: -21.99 | Q341: -11.850614 | R341: 2945.05 | S341: 23.928009 | U341: 163.57 | V341: 163.57 | W341: =(R341/R340)-1 -> -0.11756422
M342: 39885 | N342: 197.63 | P342: 34.06 | Q342: 20.822889 | R342: 3570.01 | S342: 50.226391 | U342: 197.63 | V342: 197.63 | W342: =(R342/R341)-1 -> 0.21220692
M343: 39892 | N343: 177.84 | P343: -19.79 | Q343: -10.013662 | R343: 3216.67 | S343: 35.357807 | U343: 177.84 | V343: 177.84 | W343: =(R343/R342)-1 -> -0.098974513
M344: 39899 | N344: 188.84 | P344: 11 | Q344: 6.1853351 | R344: 3424.96 | S344: 44.122672 | U344: 188.84 | V344: 188.84 | W344: =(R344/R343)-1 -> 0.064753301
M345: 39906 | N345: 220.5 | P345: 31.66 | Q345: 16.765516 | R345: 4012.04 | S345: 68.827059 | U345: 220.5 | V345: 220.5 | W345: =(R345/R344)-1 -> 0.17141222
M346: 39912 | N346: 231.29 | P346: 10.79 | Q346: 4.893424 | R346: 4210.63 | S346: 77.183747 | U346: 231.29 | V346: 231.29 | W346: =(R346/R345)-1 -> 0.049498509
M347: 39920 | N347: 243.92 | P347: 12.63 | Q347: 5.4606771 | R347: 4442.72 | S347: 86.950118 | U347: 243.92 | V347: 243.92 | W347: =(R347/R346)-1 -> 0.055120018
M348: 39927 | N348: 253.02 | P348: 9.1 | Q348: 3.7307314 | R348: 4609.66 | S348: 93.974971 | U348: 253.02 | V348: 253.02 | W348: =(R348/R347)-1 -> 0.03757608
M349: 39934 | N349: 238.98 | P349: -14.04 | Q349: -5.5489685 | R349: 4360.89 | S349: 83.506703 | U349: 238.98 | V349: 238.98 | W349: =(R349/R348)-1 -> -0.053967104
... M485: 40886 | N485: 429.35 | P485: 6.54 | Q485: 1.5467941 | R485: 8679.02 | S485: 265.21406 | U485: 429.35 | V485: 429.35 | W485: =(R485/R484)-1 -> 0.015573495
M486: 40893 | N486: 429.35 | R486: 8700.91 | S486: 266.13519 | U486: 429.35 | V486: 429.35 | W486: =(R486/R485)-1 -> 0.0025221742
M487: 40900 | N487: 447.26 | P487: 17.91 | Q487: 4.1714219 | R487: 9064.59 | S487: 281.43889 | U487: 447.26 | V487: 447.26 | W487: =(R487/R486)-1 -> 0.041797927
M488: 40907 | N488: 444.96 | P488: -2.3 | Q488: -0.51424228 | R488: 9039.07 | S488: 280.365 | U488: 444.96 | V488: 444.96 | W488: =(R488/R487)-1 -> -0.0028153507
M489: 40914 | N489: 443.99 | P489: -0.97 | Q489: -0.21799712 | R489: 9021.08 | S489: 279.60798 | U489: 443.99 | V489: 443.99 | W489: =(R489/R488)-1 -> -0.001990249
M490: 40921 | N490: 449.88 | P490: 5.89 | Q490: 1.3266065 | R490: 9144.23 | S490: 284.79015 | U490: 449.88 | V490: 449.88 | W490: =(R490/R489)-1 -> 0.013651359
M491: 40928 | N491: 461.08 | P491: 11.2 | Q491: 2.4895528 | R491: 9372.94 | S491: 294.41429 | U491: 461.08 | V491: 461.08 | W491: =(R491/R490)-1 -> 0.025011401
...

Sheet 10Y-DGS10
A1: DATASET 1 MONTHLY FREQUENCY
A2: 10Y Treasury | DGS10 | FRED
A4: Source: Board of Governors of the Federal Reserve System via FRED
A5: Series: DGS10 - Market Yield on U.S. Treasury Securities at 10-Year Constant Maturity
A6: Frequency: Monthly | Units: Percent | Not Seasonally Adjusted
A8: Date | B8: DGS10 (%)
A9: 37622 | B9: 4.05
A10: 37653 | B10: 3.9
A11: 37681 | B11: 3.81
A12: 37712 | B12: 3.96
A13: 37742 | B13: 3.57
A14: 37773 | B14: 3.33
A15: 37803 | B15: 3.98
A16: 37834 | B16: 4.45
A17: 37865 | B17: 4.27
A18: 37895 | B18: 4.29
A19: 37926 | B19: 4.3
A20: 37956 | B20: 4.27 | M20: observation_date | N20: DGS10
A21: 37987 | B21: 4.15 | M21: 37631 | N21: 4.1
A22: 38018 | B22: 4.08 | M22: 37638 | N22: 4.1
A23: 38047 | B23: 3.83 | M23: 37645 | N23: 3.97
A24: 38078 | B24: 4.35 | M24: 37652 | N24: 4.01
A25: 38108 | B25: 4.72 | M25: 37659 | N25: 3.98
A26: 38139 | B26: 4.73 | M26: 37666 | N26: 3.95
A27: 38169 | B27: 4.5 | M27: 37673 | N27: 3.89
A28: 38200 | B28: 4.28 | M28: 37680 | N28: 3.78
A29: 38231 | B29: 4.13 | M29: 37687 | N29: 3.65
A30: 38261 | B30: 4.1 | M30: 37694 | N30: 3.65
A31: 38292 | B31: 4.19 | M31: 37701 | N31: 3.97
A32: 38322 | B32: 4.23 | M32: 37708 | N32: 3.96
... A285: 46023 | B285: 4.21 | M285: 39479 | N285: 3.67
M286: 39486 | N286: 3.66
M287: 39493 | N287: 3.72
M288: 39500 | N288: 3.85
M289: 39507 | N289: 3.78
M290: 39514 | N290: 3.61
M291: 39521 | N291: 3.51
M292: 39528 | N292: 3.39
M293: 39535 | N293: 3.52
M294: 39542 | N294: 3.55
...

Sheet 2Y-DSG2
A1: DATASET 1 MONTHLY FREQUENCY
A2: 2Y Treasury | DGS2 | FRED
A4: Source: Board of Governors of the Federal Reserve System via FRED
A5: Series: DGS2 - Market Yield on U.S. Treasury Securities at 2-Year Constant Maturity
A6: Frequency: Monthly | Units: Percent | Not Seasonally Adjusted
A8: Date | B8: DGS2 (%)
A9: 37622 | B9: 1.74
A10: 37653 | B10: 1.63
A11: 37681 | B11: 1.57
A12: 37712 | B12: 1.62
A13: 37742 | B13: 1.42
A14: 37773 | B14: 1.23
A15: 37803 | B15: 1.47
A16: 37834 | B16: 1.86
A17: 37865 | B17: 1.71
A18: 37895 | B18: 1.75
A19: 37926 | B19: 1.93
A20: 37956 | B20: 1.91 | M20: observation_date | N20: DGS2
A21: 37987 | B21: 1.76 | M21: 37631 | N21: 1.8
A22: 38018 | B22: 1.74 | M22: 37638 | N22: 1.75
A23: 38047 | B23: 1.58 | M23: 37645 | N23: 1.67
A24: 38078 | B24: 2.07 | M24: 37652 | N24: 1.72
A25: 38108 | B25: 2.53 | M25: 37659 | N25: 1.69
A26: 38139 | B26: 2.76 | M26: 37666 | N26: 1.63
A27: 38169 | B27: 2.64 | M27: 37673 | N27: 1.62
A28: 38200 | B28: 2.51 | M28: 37680 | N28: 1.57
A29: 38231 | B29: 2.53 | M29: 37687 | N29: 1.47
A30: 38261 | B30: 2.58 | M30: 37694 | N30: 1.47
A31: 38292 | B31: 2.85 | M31: 37701 | N31: 1.72
A32: 38322 | B32: 3.01 | M32: 37708 | N32: 1.65
... A285: 46023 | B285: 3.54 | M285: 39479 | N285: 2.21
M286: 39486 | N286: 1.98
M287: 39493 | N287: 1.92
M288: 39500 | N288: 2.04
M289: 39507 | N289: 1.94
M290: 39514 | N290: 1.6
M291: 39521 | N291: 1.59
M292: 39528 | N292: 1.52
M293: 39535 | N293: 1.75
M294: 39542 | N294: 1.81
...

Sheet BREAKEVENPOINT INFLATION
A1: DATASET 1 MONTHLY FREQUENCY | M1: DATASET 2 DFRECUENCIA SEMANAL
A2: Break Even Inflation | T10YIE | FRED | M2: Price History: FNERXXXX
X3: FRED Graph Observations
A4: Source: Federal Reserve Bank of St. Louis via FRED | X4: Federal Reserve Economic Data, Federal Reserve Bank of St. Louis
A5: Series: T10YIE - 10-Year Breakeven Inflation Rate | X5: Link: https://fred.stlouisfed.org
A6: Frequency: Monthly | Units: Percent | Not Seasonally Adjusted | X6: Help: https://fredhelp.stlouisfed.org
X7: This data may be copyrighted. Please refer to the Terms of Use: https://fred.stlouisfed.org/legal#fred-terms-faq
A8: Date | B8: T10YIE (%) | X8: File Created: 2026-05-03 3:53 am CDT
A9: 37622 | B9: 1.75
A10: 37653 | B10: 1.91 | X10: T10YIE | Y10: 10-Year Breakeven Inflation Rate, Percent, Weekly, Not Seasonally Adjusted | Z10: Data Updated: 2026-05-01
A11: 37681 | B11: 1.86
A12: 37712 | B12: 1.77
A13: 37742 | B13: 1.66
A14: 37773 | B14: 1.61
A15: 37803 | B15: 1.87
A16: 37834 | B16: 2.12
A17: 37865 | B17: 2.09
A18: 37895 | B18: 2.21
A19: 37926 | B19: 2.34
A20: 37956 | B20: 2.28 | M20: Observation_date | N20: T10YIE
A21: 37987 | B21: 2.26 | M21: 37631 | N21: 1.7
A22: 38018 | B22: 2.32 | M22: 37638 | N22: 1.78
A23: 38047 | B23: 2.36 | M23: 37645 | N23: 1.77
A24: 38078 | B24: 2.44 | M24: 37652 | N24: 1.82
A25: 38108 | B25: 2.63 | M25: 37659 | N25: 1.86
A26: 38139 | B26: 2.59 | M26: 37666 | N26: 1.91
A27: 38169 | B27: 2.47 | M27: 37673 | N27: 1.92
A28: 38200 | B28: 2.42 | M28: 37680 | N28: 1.96
A29: 38231 | B29: 2.33 | M29: 37687 | N29: 1.9
A30: 38261 | B30: 2.37 | M30: 37694 | N30: 1.92
A31: 38292 | B31: 2.52 | M31: 37701 | N31: 1.83
A32: 38322 | B32: 2.56 | M32: 37708 | N32: 1.82
... A297: 46023 | B297: 2.31 | M297: 39563 | N297: 2.31
M298: 39570 | N298: 2.3
M299: 39577 | N299: 2.37
M300: 39584 | N300: 2.41
M301: 39591 | N301: 2.49
M302: 39598 | N302: 2.47
M303: 39605 | N303: 2.43
M304: 39612 | N304: 2.49
...

Sheet SPREAD_CREDITO
A1: DATASET 1 MONTHLY FREQUENCY | M1: DATASET 2 WEEKLY FREQUENCY
A2: Spread Crédito (BBB - Treasury) | BAA10Y | FRED | M2: Spread Crédito (BBB - Treasury) | BAA10Y | FRED
A4: Source: Federal Reserve Bank of St. Louis (FRED) | M4: Source: Federal Reserve Bank of St. Louis (FRED)
A5: Series: BAA10Y - Moody's Seasoned Baa Corporate Bond Yield Relative to 10Y Treasury | M5: Series: BAA10Y - Weekly, Ending Friday
A6: Frequency: Monthly | Units: Percent | Not Seasonally Adjusted | M6: Frequency: Weekly | Units: Percent | Not Seasonally Adjusted
A8: Date | B8: BAA10Y (Spread %) | M8: Date | N8: BAA10Y (Spread %)
A9: 37622 | B9: 3.3 | M9: 37631 | N9: 3.34
A10: 37653 | B10: 3.15 | M10: 37638 | N10: 3.29
A11: 37681 | B11: 3.14 | M11: 37645 | N11: 3.33
A12: 37712 | B12: 2.89 | M12: 37652 | N12: 3.21
A13: 37742 | B13: 2.81 | M13: 37659 | N13: 3.12
A14: 37773 | B14: 2.86 | M14: 37666 | N14: 3.15
A15: 37803 | B15: 2.64 | M15: 37673 | N15: 3.17
A16: 37834 | B16: 2.57 | M16: 37680 | N16: 3.19
A17: 37865 | B17: 2.52 | M17: 37687 | N17: 3.25
A18: 37895 | B18: 2.44 | M18: 37694 | N18: 3.25
A19: 37926 | B19: 2.36 | M19: 37701 | N19: 3.07
A20: 37956 | B20: 2.33 | M20: 37708 | N20: 3.02
... A285: 46023 | B285: 1.67 | M285: 39563 | N285: 3.18
M286: 39570 | N286: 3.07
M287: 39577 | N287: 3.04
M288: 39584 | N288: 3.06
M289: 39591 | N289: 3.07
M290: 39598 | N290: 3.04
M291: 39605 | N291: 3.03
M292: 39612 | N292: 2.93
M293: 39619 | N293: 2.94
M294: 39626 | N294: 2.98
M295: 39633 | N295: 3.06
M296: 39640 | N296: 3.13
M297: 39647 | N297: 3.2
... M1208: 46024 | N1208: 1.74

Sheet VIX
A1: DATASET 1 MONTHLY FREQUENCY | M1: DATASET 2 WEEKLY FREQUENCY
A2: VIX (Cambio Mensual) | VIXCLS | FRED | M2: VIX (Cambio Mensual) | VIXCLS | FRED
A4: Source: Chicago Board Options Exchange via FRED | M4: Source: Chicago Board Options Exchange via FRED
A5: Series: VIXCLS - CBOE Volatility Index: VIX | M5: Series: VIXCLS - Weekly, Ending Friday
A6: Frequency: Monthly | Units: Index | Not Seasonally Adjusted | M6: Frequency: Weekly | Units: Index | Not Seasonally Adjusted
A8: Date | B8: VIXCLS (Index) | M8: Date | N8: VIXCLS (Index)
A9: 37622 | B9: 27.42 | M9: 37631 | N9: 24.83
A10: 37653 | B10: 32.22 | M10: 37638 | N10: 25.14
A11: 37681 | B11: 30.63 | M11: 37645 | N11: 28.91
A12: 37712 | B12: 23.99 | M12: 37652 | N12: 32.07
A13: 37742 | B13: 20.24 | M13: 37659 | N13: 32.84
A14: 37773 | B14: 20.36 | M14: 37666 | N14: 33.66
A15: 37803 | B15: 19.16 | M15: 37673 | N15: 30.96
A16: 37834 | B16: 19.27 | M16: 37680 | N16: 31.16
A17: 37865 | B17: 19.53 | M17: 37687 | N17: 31.02
A18: 37895 | B18: 18.02 | M18: 37694 | N18: 32.63
A19: 37926 | B19: 17.4 | M19: 37701 | N19: 30.57
A20: 37956 | B20: 16.83 | M20: 37708 | N20: 28.62
... A285: 46023 | B285: 16.18 | M285: 39563 | N285: 20.26
M286: 39570 | N286: 19.55
M287: 39577 | N287: 19.13
M288: 39584 | N288: 17.24
M289: 39591 | N289: 18.16
M290: 39598 | N290: 18.67
M291: 39605 | N291: 20.61
M292: 39612 | N292: 22.99
M293: 39619 | N293: 21.75
M294: 39626 | N294: 22.71
M295: 39633 | N295: 24.58
M296: 39640 | N296: 25.45
M297: 39647 | N297: 26.24
... M1208: 46024 | N1208: 14.5

Sheet FED_FUNDS
A1: DATASET 1 MONTHLY FREQUENCY
A2: Federal Funds Rate | FEDFUNDS | FRED
A4: Source: Board of Governors of the Federal Reserve System via FRED
A5: Series: FEDFUNDS - Federal Funds Effective Rate
A6: Frequency: Monthly | Units: Percent | Not Seasonally Adjusted
A8: Date | B8: FEDFUNDS (%)
A9: 37622 | B9: 1.24
A10: 37653 | B10: 1.26
A11: 37681 | B11: 1.25
A12: 37712 | B12: 1.26
A13: 37742 | B13: 1.26
A14: 37773 | B14: 1.22
A15: 37803 | B15: 1.01
A16: 37834 | B16: 1.03
A17: 37865 | B17: 1.01
A18: 37895 | B18: 1.01
A19: 37926 | B19: 1
A20: 37956 | B20: 0.98
... A285: 46023 | B285: 3.64

Sheet CPI
A1: DATASET 1 MONTHLY FREQUENCY
A2: ACPI YoY | CPIAUCSL | FRED
A4: Source: U.S. Bureau of Labor Statistics via FRED
A5: Series: CPIAUCSL - Consumer Price Index for All Urban Consumers (data from 2002 for YoY)
A6: Frequency: Monthly | YoY % change calculated | Seasonally Adjusted
A8: Date | B8: CPIAUCSL (Index) | C8: CPI YoY (%)
A9: 37257 | B9: 177.7
A10: 37288 | B10: 178
A11: 37316 | B11: 178.5
A12: 37347 | B12: 179.3
A13: 37377 | B13: 179.5
A14: 37408 | B14: 179.6
A15: 37438 | B15: 180
A16: 37469 | B16: 180.5
A17: 37500 | B17: 180.8
A18: 37530 | B18: 181.2
A19: 37561 | B19: 181.5
A20: 37591 | B20: 181.8
A21: 37622 | B21: 182.6 | C21: 2.7575
A22: 37653 | B22: 183.6 | C22: 3.1461
A23: 37681 | B23: 183.9 | C23: 3.0252
A24: 37712 | B24: 183.2 | C24: 2.1751
A25: 37742 | B25: 182.9 | C25: 1.8942
A26: 37773 | B26: 183.1 | C26: 1.9488
A27: 37803 | B27: 183.7 | C27: 2.0556
A28: 37834 | B28: 184.5 | C28: 2.2161
A29: 37865 | B29: 185.1 | C29: 2.3783
A30: 37895 | B30: 184.9 | C30: 2.0419
A31: 37926 | B31: 185 | C31: 1.9284
A32: 37956 | B32: 185.5 | C32: 2.0352
... A298: 46082 | B298: 330.293 | C298: 3.286

Sheet INDUSTRIAL_PROD
A1: DATASET 1 MONTHLY FREQUENCY
A2: Industrial Production | INDPRO | FRED
A4: Source: Board of Governors of the Federal Reserve System via FRED
A5: Series: INDPRO - Industrial Production: Total Index (2017=100)
A6: Frequency: Monthly | Seasonally Adjusted
A8: Date | B8: INDPRO (Index 2017=100)
A9: 37622 | B9: 91.2361
A10: 37653 | B10: 91.3445
A11: 37681 | B11: 91.1044
A12: 37712 | B12: 90.5617
A13: 37742 | B13: 90.537
A14: 37773 | B14: 90.6527
A15: 37803 | B15: 91.1185
A16: 37834 | B16: 90.9197
A17: 37865 | B17: 91.5059
A18: 37895 | B18: 91.6186
A19: 37926 | B19: 92.2329
A20: 37956 | B20: 92.2602
... A285: 46023 | B285: 101.5954

Sheet CASE_SHILLER
A1: DATASET 1 MONTHLY FREQUENCY
A2: Case-Shiller | CSUSHPISA | FRED
A4: Source: S&P Dow Jones Indices LLC via FRED
A5: Series: CSUSHPISA - S&P/Case-Shiller U.S. National Home Price Index
A6: Frequency: Monthly | Index Jan 2000=100 | Not Seasonally Adjusted
A8: Date | B8: CSUSHPISA (Index)
A9: 37622 | B9: 128.462
A10: 37653 | B10: 129.357
A11: 37681 | B11: 130.148
A12: 37712 | B12: 130.884
A13: 37742 | B13: 131.735
A14: 37773 | B14: 132.649
A15: 37803 | B15: 133.777
A16: 37834 | B16: 134.968
A17: 37865 | B17: 136.295
A18: 37895 | B18: 137.533
A19: 37926 | B19: 138.795
A20: 37956 | B20: 140.182
... A285: 46023 | B285: 331.801

Sheet HOUSING_STARTS
A1: DATASET 1 MONTHLY FREQUENCY
A2: Housing Starts | HOUST | FRED
A4: Source: U.S. Census Bureau / HUD via FRED
A5: Series: HOUST - New Privately-Owned Housing Units Started: Total Units
A6: Frequency: Monthly | Thousands of Units | Seasonally Adjusted Annual Rate
A8: Date | B8: HOUST (thousands)
A9: 37622 | B9: 1853
A10: 37653 | B10: 1629
A11: 37681 | B11: 1726
A12: 37712 | B12: 1643
A13: 37742 | B13: 1751
A14: 37773 | B14: 1867
A15: 37803 | B15: 1897
A16: 37834 | B16: 1833
A17: 37865 | B17: 1939
A18: 37895 | B18: 1967
A19: 37926 | B19: 2083
A20: 37956 | B20: 2057
... A285: 46023 | B285: 1398

Sheet BUILDING_PERMITS
A1: DATASET 1 MONTHLY FREQUENCY
A2: Building Permits | PERMIT | FRED
A4: Source: U.S. Census Bureau / HUD via FRED
A5: Series: PERMIT - New Privately-Owned Housing Units Authorized in Permit-Issuing Places
A6: Frequency: Monthly | Thousands of Units | Seasonally Adjusted Annual Rate
A8: Date | B8: PERMIT (thousands)
A9: 37622 | B9: 1808
A10: 37653 | B10: 1854
A11: 37681 | B11: 1757
A12: 37712 | B12: 1803
A13: 37742 | B13: 1835
A14: 37773 | B14: 1875
A15: 37803 | B15: 1885
A16: 37834 | B16: 1966
A17: 37865 | B17: 1961
A18: 37895 | B18: 2012
A19: 37926 | B19: 1918
A20: 37956 | B20: 1987
... A285: 46023 | B285: 1386
